<?xml version="1.0"?>

<robot name="Arm_robo">
   <material name="black">
     <color rgba="0 0 0 0"/>
   </material>

   <!-- New materials for red and yellow -->
   <material name="red">
     <color rgba="1 0 0 1.0"/>
   </material>

   <material name="yellow">
     <color rgba="1 1 0 1.0"/>
   </material>

    <!-- Fixed base link -->
    <link name="base_link">
        <visual>
            <origin xyz="0 0 0" rpy="0 0 0"/>
            <geometry>
                <box size="0.1 0.1 0.1"/>
            </geometry>
            <material name="black"/>
        </visual>
    </link>
    
    <!-- Link 1 -->
    <link name="link_1">
        <visual>
            <origin xyz="0.5 0 0" rpy="0 0 0"/>
            <geometry>
                <box size="1 0.1 0.1"/>
            </geometry>
            <material name="red"/>
        </visual>
    </link>

    <!-- Link 2 -->
    <link name="link_2">
        <visual>
            <origin xyz="0.5 0 0" rpy="0 0 0.1"/> <!-- Introduced a slight bend -->
            <geometry>
                <box size="1 0.1 0.1"/>
            </geometry>
            <material name="yellow"/>
        </visual>
    </link>
    
    <!-- Joint 1 -->
    <joint name="Revolute_joint_1" type="revolute">
        <origin xyz="0 0 0" rpy="0 0 0.5236"/> <!-- 30 degrees in radians is 0.5236 -->
        <parent link="base_link"/>
        <child link="link_1"/>
        <axis xyz="0 0 1"/>
        <limit effort="10" velocity="1.0" lower="-1.57" upper="1.57"/>
    </joint>

    <!-- Joint 2 -->
    <joint name="Revolute_joint_2" type="revolute">
        <origin xyz="1 0 0" rpy="0 0 0.32"/> <!-- -30 degrees in radians is -0.5236 -->
        <parent link="link_1"/>
        <child link="link_2"/>
        <axis xyz="0 0 1"/>
        <limit effort="10" velocity="1.0" lower="-1.57" upper="1.57"/>
    </joint> 
</robot>
